Workbook

Sheet Dashboard
E2: Retail Sales Performance Dashboard
E3: 2025 | Sales, Profitability & Performance Overview
A6: TOTAL SALES | D6: TOTAL PROFIT | G6: TOTAL ORDERS | J6: AVERAGE ORDER VALUE | M6: OVERALL PROFIT MARGIN
A7: =Analysis!B2 -> 6502061.5 | D7: =Analysis!B3 -> 809241.09 | G7: =Analysis!B4 -> 350 | J7: =Analysis!B5 -> 18577.319 | M7: =Analysis!B6 -> 0.12445916
A65: Source: SalesData | 350 transactions | Jan-Dec 2025
A68: KEY BUSINESS INSIGHTS
A69: Regional Performance: North recorded the highest total sales at ₹20,84,611.50, generating ₹2,63,281.07 in profit at a 12.63% profit margin from 87 orders.
A72: Monthly Performance: October recorded the highest monthly sales at ₹8,70,920.00 from 39 orders, with an average order value of ₹22,331.28.
A75: Category Performance: Electronics recorded the highest category sales at ₹38,48,855.00, generating ₹4,70,476.67 in profit with a 12.22% profit margin.
A78: Discount & Profitability: The dataset shows a generally declining profit margin at higher discount levels, although the relationship is not strictly decreasing. Profit margin was 16.90% at 0% discount, 12.92% at 5%, 14.59% at 10%, 10.40% at 15%, and 7.57% at 20%.
A82: RECOMMENDED ACTIONS
A83: 1. Discount Strategy: The business should closely monitor discount levels, particularly discounts of 15% and 20%, as the observed profit margin declines to 10.40% and 7.57% respectively. While the relationship is not strictly linear, higher discount levels in this dataset are associated with lower observed profit margins.
A86: 2. Regional Strategy: The business should evaluate regional performance using Sales, Profit, Order Count, and AOV together rather than relying on order volume alone. The North region generated the highest sales with fewer orders than West, making AOV an important metric for understanding regional performance.
A89: 3. Category Strategy: The business should evaluate category performance using Sales, Profit, Order Count, AOV, and Profit Margin together. Category-level profitability should be compared with the overall 12.45% margin, with further investigation for categories whose margins are below the overall benchmark.
A92: 4. Channel Strategy: The business should monitor discount levels by sales channel alongside Sales, Profit, Order Count, AOV, and Profit Margin. Since the two channels show different observed profit margins, further analysis of channel-level discounting and product mix could help explain the difference.

Sheet Analysis
A1: KPI | B1: VALUE
A2: Total Sales | B2: =SUM(SalesData[Sales]) -> 6502061.5
A3: Total Profit | B3: =SUM(SalesData[Profit]) -> 809241.09
A4: Total Orders | B4: =COUNTA(SalesData[Order_ID]) -> 350
A5: Average Order Value | B5: =SUM(SalesData[Sales])/COUNTA(SalesData[Order_ID]) -> 18577.319
A6: Overall Profit Margin | B6: =SUM(SalesData[Profit])/SUM(SalesData[Sales]) -> 0.12445916

Sheet Pivot_Analysis
A3: Region | B3: Sum of Sales | C3: Sum of Profit | D3: Count of Order_ID | E3: Regional AOV | F3: Regional Profit Margin | I3: Category | J3: Sum of Sales | K3: Sum of Profit | L3: Count of Order_ID | M3: Category AOV | N3: Category Profit Margin
A4: East | B4: 1241286.5 | C4: 142704.81 | D4: 79 | E4: =B4/D4 -> 15712.487 | F4: =C4/B4 -> 0.11496525 | I4: Accessories | J4: 352320 | K4: 43373.25 | L4: 96 | M4: =J4/L4 -> 3670 | N4: =K4/J4 -> 0.12310754
A5: North | B5: 2084611.5 | C5: 263281.07 | D5: 87 | E5: =B5/D5 -> 23961.052 | F5: =C5/B5 -> 0.12629743 | I5: Electronics | J5: 3848855 | K5: 470476.67 | L5: 79 | M5: =J5/L5 -> 48719.684 | N5: =K5/J5 -> 0.12223809
A6: South | B6: 1194332.5 | C6: 138774.53 | D6: 83 | E6: =B6/D6 -> 14389.548 | F6: =C6/B6 -> 0.11619422 | I6: Furniture | J6: 2139770 | K6: 275807.17 | L6: 75 | M6: =J6/L6 -> 28530.267 | N6: =K6/J6 -> 0.12889571
A7: Unknown | B7: 55676 | C7: 9435.49 | D7: 3 | E7: =B7/D7 -> 18558.667 | F7: =C7/B7 -> 0.16947141 | I7: Office Supplies | J7: 161116.5 | K7: 19584 | L7: 100 | M7: =J7/L7 -> 1611.165 | N7: =K7/J7 -> 0.1215518
A8: West | B8: 1926155 | C8: 255045.19 | D8: 98 | E8: =B8/D8 -> 19654.643 | F8: =C8/B8 -> 0.13241156 | I8: Grand Total | J8: 6502061.5 | K8: 809241.09 | L8: 350 | M8: =J8/L8 -> 18577.319 | N8: =K8/J8 -> 0.12445916
A9: Grand Total | B9: 6502061.5 | C9: 809241.09 | D9: 350 | E9: =B9/D9 -> 18577.319 | F9: =C9/B9 -> 0.12445916
A12: Sales_Channel | B12: Sum of Sales | C12: Sum of Profit | D12: Count of Order_ID | E12: Channel AOV | F12: Channel Profit Margin | I12: Product | J12: Sum of Sales | K12: Sum of Profit | L12: Count of Order_ID | M12: Product AOV | N12: Product Profit Margin
A13: Online | B13: 3485907.5 | C13: 469770.13 | D13: 183 | E13: =B13/D13 -> 19048.675 | F13: =C13/B13 -> 0.13476265 | I13: Bookshelf | J13: 413400 | K13: 54493.1 | L13: 18 | M13: =J13/L13 -> 22966.667 | N13: =K13/J13 -> 0.13181688
A14: Retail Store | B14: 3016154 | C14: 339470.96 | D14: 167 | E14: =B14/D14 -> 18060.802 | F14: =C14/B14 -> 0.11255094 | I14: Desk | J14: 720000 | K14: 106866.63 | L14: 18 | M14: =J14/L14 -> 40000 | N14: =K14/J14 -> 0.14842588
A15: Grand Total | B15: 6502061.5 | C15: 809241.09 | D15: 350 | E15: =B15/D15 -> 18577.319 | F15: =C15/B15 -> 0.12445916 | I15: Filing Cabinet | J15: 469170 | K15: 59036.62 | L15: 19 | M15: =J15/L15 -> 24693.158 | N15: =K15/J15 -> 0.12583204
I16: Headphones | J16: 177625 | K16: 24087.01 | L16: 24 | M16: =J16/L16 -> 7401.0417 | N16: =K16/J16 -> 0.13560597
I17: Keyboard | J17: 79830 | K17: 9240.98 | L17: 12 | M17: =J17/L17 -> 6652.5 | N17: =K17/J17 -> 0.11575824
I18: Laptop | J18: 2025400 | K18: 261414.99 | L18: 13 | M18: =J18/L18 -> 155800 | N18: =K18/J18 -> 0.12906833
I19: Laptop Bag | J19: 114120 | K19: 14024.9 | L19: 27 | M19: =J19/L19 -> 4226.6667 | N19: =K19/J19 -> 0.12289607
I20: Monitor | J20: 1566000 | K20: 175733.69 | L20: 30 | M20: =J20/L20 -> 52200 | N20: =K20/J20 -> 0.11221819
I21: Mouse | J21: 59850 | K21: 8117.72 | L21: 23 | M21: =J21/L21 -> 2602.1739 | N21: =K21/J21 -> 0.13563442
I22: Notebook | J22: 11166 | K22: 1099.46 | L22: 30 | M22: =J22/L22 -> 372.2 | N22: =K22/J22 -> 0.098464983
I23: Office Chair | J23: 537200 | K23: 55410.82 | L23: 20 | M23: =J23/L23 -> 26860 | N23: =K23/J23 -> 0.10314747
I24: Printer Ink | J24: 104640 | K24: 13019.53 | L24: 24 | M24: =J24/L24 -> 4360 | N24: =K24/J24 -> 0.12442211
I25: Printer Paper | J25: 26797.5 | K25: 3109.61 | L25: 20 | M25: =J25/L25 -> 1339.875 | N25: =K25/J25 -> 0.11604105
I26: Stapler | J26: 18513 | K26: 2355.4 | L26: 26 | M26: =J26/L26 -> 712.03846 | N26: =K26/J26 -> 0.12722951
I27: USB Hub | J27: 60210 | K27: 7128.56 | L27: 22 | M27: =J27/L27 -> 2736.8182 | N27: =K27/J27 -> 0.11839495
... I29: Grand Total | J29: 6502061.5 | K29: 809241.09 | L29: 350 | M29: =J29/L29 -> 18577.319 | N29: =K29/J29 -> 0.12445916
A33: Months | B33: Sum of Sales | C33: Sum of Profit | D33: Count of Order_ID | E33: Monthly AOV | F33: Monthly Profit Margin | I33: Discount | J33: Sum of Sales | K33: Sum of Profit | L33: Count of Order_ID | M33: Discount Profit Margin | N33: Discount AOV
A34: Jan | B34: 751646 | C34: 96153.94 | D34: 27 | E34: =B34/D34 -> 27838.741 | F34: =C34/B34 -> 0.1279245 | I34: 0 | J34: 1249840 | K34: 211248.58 | L34: 66 | M34: =K34/J34 -> 0.1690205 | N34: =J34/L34 -> 18936.97
A35: Feb | B35: 641929 | C35: 87664.67 | D35: 25 | E35: =B35/D35 -> 25677.16 | F35: =C35/B35 -> 0.13656443 | I35: 0.05 | J35: 1033514.5 | K35: 133549.09 | L35: 63 | M35: =K35/J35 -> 0.1292184 | N35: =J35/L35 -> 16404.992
A36: Mar | B36: 793872 | C36: 110200.84 | D36: 42 | E36: =B36/D36 -> 18901.714 | F36: =C36/B36 -> 0.13881437 | I36: 0.1 | J36: 1434366 | K36: 209233.86 | L36: 70 | M36: =K36/J36 -> 0.14587202 | N36: =J36/L36 -> 20490.943
A37: Apr | B37: 377306.5 | C37: 50406.98 | D37: 23 | E37: =B37/D37 -> 16404.63 | F37: =C37/B37 -> 0.1335969 | I37: 0.15 | J37: 1566941 | K37: 163035.66 | L37: 83 | M37: =K37/J37 -> 0.1040471 | N37: =J37/L37 -> 18878.807
A38: May | B38: 569946 | C38: 49662.69 | D38: 30 | E38: =B38/D38 -> 18998.2 | F38: =C38/B38 -> 0.087135781 | I38: 0.2 | J38: 1217400 | K38: 92173.9 | L38: 68 | M38: =K38/J38 -> 0.075713734 | N38: =J38/L38 -> 17902.941
A39: Jun | B39: 564767.5 | C39: 70659.78 | D39: 35 | E39: =B39/D39 -> 16136.214 | F39: =C39/B39 -> 0.12511304 | I39: Grand Total | J39: 6502061.5 | K39: 809241.09 | L39: 350 | M39: =K39/J39 -> 0.12445916 | N39: =J39/L39 -> 18577.319
A40: Jul | B40: 372801 | C40: 51832.38 | D40: 26 | E40: =B40/D40 -> 14338.5 | F40: =C40/B40 -> 0.13903498
A41: Aug | B41: 488322.5 | C41: 59238.46 | D41: 30 | E41: =B41/D41 -> 16277.417 | F41: =C41/B41 -> 0.12131012
A42: Sep | B42: 253669 | C42: 37936.38 | D42: 23 | E42: =B42/D42 -> 11029.087 | F42: =C42/B42 -> 0.14955071
A43: Oct | B43: 870920 | C43: 105610.31 | D43: 39 | E43: =B43/D43 -> 22331.282 | F43: =C43/B43 -> 0.12126293 | I43: Payment Method | J43: Sum of Sales | K43: Sum of Profit | L43: Count of Order_ID | M43: Payment AOV | N43: Payment Profit Margin
A44: Nov | B44: 571056.5 | C44: 64939.7 | D44: 24 | E44: =B44/D44 -> 23794.021 | F44: =C44/B44 -> 0.11371852 | I44: Cash | J44: 1093739.5 | K44: 137156.19 | L44: 71 | M44: =J44/L44 -> 15404.782 | N44: =K44/J44 -> 0.12540115
A45: Dec | B45: 245825.5 | C45: 24934.96 | D45: 26 | E45: =B45/D45 -> 9454.8269 | F45: =C45/B45 -> 0.10143358 | I45: Credit Card | J45: 1521221 | K45: 175626.63 | L45: 65 | M45: =J45/L45 -> 23403.4 | N45: =K45/J45 -> 0.11545109
A46: Grand Total | B46: 6502061.5 | C46: 809241.09 | D46: 350 | E46: =B46/D46 -> 18577.319 | F46: =C46/B46 -> 0.12445916 | I46: Debit Card | J46: 1281141.5 | K46: 176289.12 | L46: 77 | M46: =J46/L46 -> 16638.201 | N46: =K46/J46 -> 0.13760316
I47: Net Banking | J47: 1225479 | K47: 159942.35 | L47: 68 | M47: =J47/L47 -> 18021.75 | N47: =K47/J47 -> 0.13051415
I48: UPI | J48: 1380480.5 | K48: 160226.8 | L48: 69 | M48: =J48/L48 -> 20006.964 | N48: =K48/J48 -> 0.11606596
...

Sheet Chart 

Sheet Chart_Data
A1: Month | B1: Sales | D1: Category | E1: Sales | G1: Sales Channel | H1: Sales | J1: Category | K1: Profit | M1: Discount | N1: Profit Margin | P1: Region | Q1: Sales
A2: =Pivot_Analysis!A34 -> Jan | B2: =Pivot_Analysis!B34 -> 751646 | D2: =Pivot_Analysis!I4 -> Accessories | E2: =Pivot_Analysis!J4 -> 352320 | G2: =Pivot_Analysis!A13 -> Online | H2: =Pivot_Analysis!B13 -> 3485907.5 | J2: =Pivot_Analysis!I4 -> Accessories | K2: =Pivot_Analysis!K4 -> 43373.25 | M2: =Pivot_Analysis!I34 -> 0 | N2: =Pivot_Analysis!M34 -> 0.1690205 | P2: =Pivot_Analysis!A4 -> East | Q2: =Pivot_Analysis!B4 -> 1241286.5
A3: =Pivot_Analysis!A35 -> Feb | B3: =Pivot_Analysis!B35 -> 641929 | D3: =Pivot_Analysis!I5 -> Electronics | E3: =Pivot_Analysis!J5 -> 3848855 | G3: =Pivot_Analysis!A14 -> Retail Store | H3: =Pivot_Analysis!B14 -> 3016154 | J3: =Pivot_Analysis!I5 -> Electronics | K3: =Pivot_Analysis!K5 -> 470476.67 | M3: =Pivot_Analysis!I35 -> 0.05 | N3: =Pivot_Analysis!M35 -> 0.1292184 | P3: =Pivot_Analysis!A5 -> North | Q3: =Pivot_Analysis!B5 -> 2084611.5
A4: =Pivot_Analysis!A36 -> Mar | B4: =Pivot_Analysis!B36 -> 793872 | D4: =Pivot_Analysis!I6 -> Furniture | E4: =Pivot_Analysis!J6 -> 2139770 | J4: =Pivot_Analysis!I6 -> Furniture | K4: =Pivot_Analysis!K6 -> 275807.17 | M4: =Pivot_Analysis!I36 -> 0.1 | N4: =Pivot_Analysis!M36 -> 0.14587202 | P4: =Pivot_Analysis!A6 -> South | Q4: =Pivot_Analysis!B6 -> 1194332.5
A5: =Pivot_Analysis!A37 -> Apr | B5: =Pivot_Analysis!B37 -> 377306.5 | D5: =Pivot_Analysis!I7 -> Office Supplies | E5: =Pivot_Analysis!J7 -> 161116.5 | J5: =Pivot_Analysis!I7 -> Office Supplies | K5: =Pivot_Analysis!K7 -> 19584 | M5: =Pivot_Analysis!I37 -> 0.15 | N5: =Pivot_Analysis!M37 -> 0.1040471 | P5: =Pivot_Analysis!A7 -> Unknown | Q5: =Pivot_Analysis!B7 -> 55676
A6: =Pivot_Analysis!A38 -> May | B6: =Pivot_Analysis!B38 -> 569946 | M6: =Pivot_Analysis!I38 -> 0.2 | N6: =Pivot_Analysis!M38 -> 0.075713734 | P6: =Pivot_Analysis!A8 -> West | Q6: =Pivot_Analysis!B8 -> 1926155
A7: =Pivot_Analysis!A39 -> Jun | B7: =Pivot_Analysis!B39 -> 564767.5
A8: =Pivot_Analysis!A40 -> Jul | B8: =Pivot_Analysis!B40 -> 372801
A9: =Pivot_Analysis!A41 -> Aug | B9: =Pivot_Analysis!B41 -> 488322.5
A10: =Pivot_Analysis!A42 -> Sep | B10: =Pivot_Analysis!B42 -> 253669
A11: =Pivot_Analysis!A43 -> Oct | B11: =Pivot_Analysis!B43 -> 870920
A12: =Pivot_Analysis!A44 -> Nov | B12: =Pivot_Analysis!B44 -> 571056.5
A13: =Pivot_Analysis!A45 -> Dec | B13: =Pivot_Analysis!B45 -> 245825.5

Sheet Cleaned_Sales_Data
A1: Order_ID | B1: Order_Date | C1: Customer_ID | D1: Region | E1: Category | F1: Product | G1: Quantity | H1: Unit_Price | I1: Discount | J1: Sales | K1: Profit | L1: Payment_Method | M1: Sales_Channel | N1: Profit_Margin
A2: ORD-0001 | B2: 45985 | C2: CUST-0029 | D2: North | E2: Office Supplies | F2: Notebook | G2: 2 | H2: 120 | I2: 0.05 | J2: 228 | K2: 41.12 | L2: Cash | M2: Online | N2: =SalesData[[#This Row],[Profit]]/SalesData[[#This Row],[Sales]] -> 0.18035088
A3: ORD-0002 | B3: 45960 | C3: CUST-0109 | D3: North | E3: Electronics | F3: Laptop | G3: 2 | H3: 52000 | I3: 0.05 | J3: 98800 | K3: 14163.66 | L3: UPI | M3: Online | N3: =SalesData[[#This Row],[Profit]]/SalesData[[#This Row],[Sales]] -> 0.14335688
A4: ORD-0003 | B4: 45990 | C4: CUST-0140 | D4: West | E4: Furniture | F4: Filing Cabinet | G4: 5 | H4: 7800 | I4: 0.1 | J4: 35100 | K4: 6125.26 | L4: UPI | M4: Online | N4: =SalesData[[#This Row],[Profit]]/SalesData[[#This Row],[Sales]] -> 0.17450883
A5: ORD-0004 | B5: 46015 | C5: CUST-0109 | D5: East | E5: Office Supplies | F5: Notebook | G5: 2 | H5: 120 | I5: 0.1 | J5: 216 | K5: 13.25 | L5: Net Banking | M5: Online | N5: =SalesData[[#This Row],[Profit]]/SalesData[[#This Row],[Sales]] -> 0.061342593
A6: ORD-0005 | B6: 45841 | C6: CUST-0089 | D6: East | E6: Electronics | F6: Headphones | G6: 5 | H6: 2500 | I6: 0 | J6: 12500 | K6: 2946.23 | L6: Net Banking | M6: Online | N6: =SalesData[[#This Row],[Profit]]/SalesData[[#This Row],[Sales]] -> 0.2356984
A7: ORD-0006 | B7: 45940 | C7: CUST-0076 | D7: East | E7: Furniture | F7: Office Chair | G7: 1 | H7: 8500 | I7: 0.05 | J7: 8075 | K7: 1503.49 | L7: UPI | M7: Online | N7: =SalesData[[#This Row],[Profit]]/SalesData[[#This Row],[Sales]] -> 0.18619071
A8: ORD-0007 | B8: 45709 | C8: CUST-0098 | D8: East | E8: Accessories | F8: Webcam | G8: 2 | H8: 2200 | I8: 0.1 | J8: 3960 | K8: 403.3 | L8: Debit Card | M8: Online | N8: =SalesData[[#This Row],[Profit]]/SalesData[[#This Row],[Sales]] -> 0.10184343
A9: ORD-0008 | B9: 45969 | C9: CUST-0044 | D9: South | E9: Furniture | F9: Filing Cabinet | G9: 4 | H9: 7800 | I9: 0.1 | J9: 28080 | K9: 5709.33 | L9: Cash | M9: Online | N9: =SalesData[[#This Row],[Profit]]/SalesData[[#This Row],[Sales]] -> 0.20332372
A10: ORD-0009 | B10: 46008 | C10: CUST-0084 | D10: North | E10: Furniture | F10: Office Chair | G10: 3 | H10: 8500 | I10: 0.15 | J10: 21675 | K10: 1524.59 | L10: Credit Card | M10: Retail Store | N10: =SalesData[[#This Row],[Profit]]/SalesData[[#This Row],[Sales]] -> 0.070338639
A11: ORD-0010 | B11: 45766 | C11: CUST-0128 | D11: West | E11: Accessories | F11: Mouse | G11: 3 | H11: 700 | I11: 0.05 | J11: 1995 | K11: 203.41 | L11: Cash | M11: Retail Store | N11: =SalesData[[#This Row],[Profit]]/SalesData[[#This Row],[Sales]] -> 0.1019599
A12: ORD-0011 | B12: 45957 | C12: CUST-0110 | D12: West | E12: Office Supplies | F12: Notebook | G12: 2 | H12: 120 | I12: 0.2 | J12: 192 | K12: 17.08 | L12: UPI | M12: Online | N12: =SalesData[[#This Row],[Profit]]/SalesData[[#This Row],[Sales]] -> 0.088958333
A13: ORD-0012 | B13: 45736 | C13: CUST-0041 | D13: West | E13: Electronics | F13: Headphones | G13: 4 | H13: 2500 | I13: 0.2 | J13: 8000 | K13: 1355.04 | L13: Cash | M13: Retail Store | N13: =SalesData[[#This Row],[Profit]]/SalesData[[#This Row],[Sales]] -> 0.16938
... A351: ORD-0350 | B351: 45860 | C351: CUST-0085 | D351: South | E351: Electronics | F351: Headphones | G351: 3 | H351: 2500 | I351: 0.1 | J351: 6750 | K351: 325.6 | L351: Debit Card | M351: Retail Store | N351: =SalesData[[#This Row],[Profit]]/SalesData[[#This Row],[Sales]] -> 0.048237037

Sheet Cleaning_Log
A1: Issue | B1: Field | C1: Finding | D1: Action Taken | E1: Validation
A2: Duplicate identifiers | B2: Order_ID | C2: 2 Order IDs appeared twice; the corresponding transaction details were different | D2: Reassigned the second occurrences to ORD-0351 and ORD-0352 | E2: All 350 Order_ID values verified as unique
A3: Missing values | B3: Customer_ID | C3: 3 records had blank Customer_ID values | D3: Replaced blanks with Unknown to preserve the transaction records | E3: Verified 0 blank Customer_ID values remain
A4: Missing values | B4: Region | C4: 3 records had blank Region values; available customer history did not provide a unique Region for all cases | D4: Replaced blanks with Unknown to preserve the transaction records | E4: Verified 0 blank Region values remain
A5: Inconsistent capitalization | B5: Category | C5: Category values contained inconsistent capitalization, including uppercase variants | D5: Standardized category names to Accessories, Electronics, Furniture, and Office Supplies | E5: Verified exactly 4 standardized category values remain
A6: Data validation | B6: Sales | C6: Sales values needed to be checked against Quantity, Unit Price, and Discount | D6: Checked all 350 records using Quantity × Unit_Price × (1 − Discount) | E6: 350/350 records matched
A7: Data validation | B7: Product / Category | C7: Products needed to be checked for category consistency | D7: Compared Product against Category across all records | E7: 350/350 records consistent
A8: Data validation | B8: Text fields | C8: Text fields needed to be checked for extra leading/trailing/hidden spaces | D8: Applied TRIM/CLEAN-based validation to Customer_ID, Region, Category, Product, Payment_Method, and Sales_Channel | E8: 350/350 records clean
A9: Data validation | B9: Order_ID | C9: Order_ID uniqueness needed to be confirmed after duplicate corrections | D9: Checked occurrence count for every Order_ID | E9: 350/350 IDs unique

Sheet Data_Dictionary
A1: Column | B1: Description | C1: Type / Example
A2: Order_ID | B2: Unique order identifier; a few intentional duplicates are included for cleaning practice. | C2: Text / ORD-0001
A3: Order_Date | B3: Date the order was placed. | C3: Date
A4: Customer_ID | B4: Customer identifier; a few blanks are intentional. | C4: Text / CUST-0001
A5: Region | B5: Sales region; a few blanks are intentional. | C5: North / South / East / West
A6: Category | B6: Product category; a few capitalization inconsistencies are intentional. | C6: Electronics
A7: Product | B7: Product purchased. | C7: Laptop
A8: Quantity | B8: Number of units purchased. | C8: 1–6
A9: Unit_Price | B9: Price per unit before discount. | C9: ₹52,000
A10: Discount | B10: Discount applied to the order. | C10: 0%–20%
A11: Sales | B11: Net sales value after discount. | C11: ₹46,800
A12: Profit | B12: Estimated profit for the order. | C12: ₹6,000
... A14: Sales_Channel | B14: Where the order was completed. | C14: Online / Retail Store

Sheet Raw_Sales_Data
A1: Order_ID | B1: Order_Date | C1: Customer_ID | D1: Region | E1: Category | F1: Product | G1: Quantity | H1: Unit_Price | I1: Discount | J1: Sales | K1: Profit | L1: Payment_Method | M1: Sales_Channel
A2: ORD-0001 | B2: 45985 | C2: CUST-0029 | D2: North | E2: Office Supplies | F2: Notebook | G2: 2 | H2: 120 | I2: 0.05 | J2: 228 | K2: 41.12 | L2: Cash | M2: Online
A3: ORD-0002 | B3: 45960 | C3: CUST-0109 | D3: North | E3: Electronics | F3: Laptop | G3: 2 | H3: 52000 | I3: 0.05 | J3: 98800 | K3: 14163.66 | L3: UPI | M3: Online
A4: ORD-0003 | B4: 45990 | C4: CUST-0140 | D4: West | E4: Furniture | F4: Filing Cabinet | G4: 5 | H4: 7800 | I4: 0.1 | J4: 35100 | K4: 6125.26 | L4: UPI | M4: Online
A5: ORD-0004 | B5: 46015 | C5: CUST-0109 | D5: East | E5: Office Supplies | F5: Notebook | G5: 2 | H5: 120 | I5: 0.1 | J5: 216 | K5: 13.25 | L5: Net Banking | M5: Online
A6: ORD-0005 | B6: 45841 | C6: CUST-0089 | D6: East | E6: Electronics | F6: Headphones | G6: 5 | H6: 2500 | I6: 0 | J6: 12500 | K6: 2946.23 | L6: Net Banking | M6: Online
A7: ORD-0006 | B7: 45940 | C7: CUST-0076 | D7: East | E7: Furniture | F7: Office Chair | G7: 1 | H7: 8500 | I7: 0.05 | J7: 8075 | K7: 1503.49 | L7: UPI | M7: Online
A8: ORD-0007 | B8: 45709 | C8: CUST-0098 | D8: East | E8: Accessories | F8: Webcam | G8: 2 | H8: 2200 | I8: 0.1 | J8: 3960 | K8: 403.3 | L8: Debit Card | M8: Online
A9: ORD-0008 | B9: 45969 | C9: CUST-0044 | D9: South | E9: Furniture | F9: Filing Cabinet | G9: 4 | H9: 7800 | I9: 0.1 | J9: 28080 | K9: 5709.33 | L9: Cash | M9: Online
A10: ORD-0009 | B10: 46008 | C10: CUST-0084 | D10: North | E10: Furniture | F10: Office Chair | G10: 3 | H10: 8500 | I10: 0.15 | J10: 21675 | K10: 1524.59 | L10: Credit Card | M10: Retail Store
A11: ORD-0010 | B11: 45766 | C11: CUST-0128 | D11: West | E11: Accessories | F11: Mouse | G11: 3 | H11: 700 | I11: 0.05 | J11: 1995 | K11: 203.41 | L11: Cash | M11: Retail Store
A12: ORD-0011 | B12: 45957 | C12: CUST-0110 | D12: West | E12: Office Supplies | F12: Notebook | G12: 2 | H12: 120 | I12: 0.2 | J12: 192 | K12: 17.08 | L12: UPI | M12: Online
A13: ORD-0012 | B13: 45736 | C13: CUST-0041 | D13: West | E13: Electronics | F13: Headphones | G13: 4 | H13: 2500 | I13: 0.2 | J13: 8000 | K13: 1355.04 | L13: Cash | M13: Retail Store
... A41: ORD-0040 | B41: 45837 | C41: CUST-0131 | D41: West | E41: Office Supplies | F41: Printer Paper | G41: 1 | H41: 450 | I41: 0.1 | J41: 405 | K41: 29.8 | L41: Debit Card | M41: Online
A42: ORD-0041 | B42: 45713 | D42: East | E42: Office Supplies | F42: Stapler | G42: 5 | H42: 220 | I42: 0.2 | J42: 880 | K42: 26.4 | L42: Cash | M42: Online
A43: ORD-0042 | B43: 45788 | C43: CUST-0012 | D43: West | E43: Electronics | F43: Monitor | G43: 3 | H43: 14500 | I43: 0.15 | J43: 36975 | K43: 1430.78 | L43: Debit Card | M43: Retail Store
A44: ORD-0043 | B44: 45997 | C44: CUST-0032 | D44: East | E44: Office Supplies | F44: Stapler | G44: 3 | H44: 220 | I44: 0.15 | J44: 561 | K44: 78.01 | L44: Cash | M44: Online
A45: ORD-0044 | B45: 45756 | C45: CUST-0108 | D45: West | E45: Furniture | F45: Bookshelf | G45: 4 | H45: 6500 | I45: 0.2 | J45: 20800 | K45: 2982.64 | L45: Debit Card | M45: Retail Store
A46: ORD-0045 | B46: 45765 | C46: CUST-0111 | D46: East | E46: Accessories | F46: Laptop Bag | G46: 4 | H46: 1800 | I46: 0.05 | J46: 6840 | K46: 986.93 | L46: Credit Card | M46: Online
A47: ORD-0046 | B47: 45803 | C47: CUST-0132 | D47: East | E47: Electronics | F47: Monitor | G47: 6 | H47: 14500 | I47: 0.1 | J47: 78300 | K47: 6337.8 | L47: Credit Card | M47: Online
A48: ORD-0047 | B48: 45670 | C48: CUST-0012 | D48: South | E48: Accessories | F48: USB Hub | G48: 4 | H48: 900 | I48: 0.15 | J48: 3060 | K48: 518 | L48: Cash | M48: Online
A49: ORD-0048 | B49: 46014 | C49: CUST-0099 | D49: West | E49: Accessories | F49: Mouse | G49: 2 | H49: 700 | I49: 0 | J49: 1400 | K49: 311.96 | L49: UPI | M49: Retail Store
A50: ORD-0049 | B50: 45770 | C50: CUST-0046 | D50: West | E50: Electronics | F50: Monitor | G50: 1 | H50: 14500 | I50: 0.15 | J50: 12325 | K50: 601.88 | L50: Net Banking | M50: Retail Store
A51: ORD-0050 | B51: 45884 | C51: CUST-0130 | D51: West | E51: Accessories | F51: Mouse | G51: 6 | H51: 700 | I51: 0.15 | J51: 3570 | K51: 355.25 | L51: Credit Card | M51: Retail Store
A52: ORD-0051 | B52: 45924 | C52: CUST-0125 | D52: South | E52: Office Supplies | F52: Stapler | G52: 1 | H52: 220 | I52: 0.1 | J52: 198 | K52: 16.34 | L52: Debit Card | M52: Retail Store
A53: ORD-0052 | B53: 45934 | C53: CUST-0021 | E53: Furniture | F53: Desk | G53: 4 | H53: 12000 | I53: 0.05 | J53: 45600 | K53: 8004.03 | L53: UPI | M53: Retail Store
A54: ORD-0053 | B54: 45866 | C54: CUST-0085 | D54: West | E54: Accessories | F54: USB Hub | G54: 2 | H54: 900 | I54: 0.15 | J54: 1530 | K54: 137.42 | L54: Cash | M54: Online
A55: ORD-0054 | B55: 45952 | C55: CUST-0098 | D55: West | E55: Electronics | F55: Keyboard | G55: 3 | H55: 1800 | I55: 0.15 | J55: 4590 | K55: 753 | L55: Net Banking | M55: Online
A56: ORD-0055 | B56: 45907 | C56: CUST-0057 | D56: East | E56: Accessories | F56: Laptop Bag | G56: 1 | H56: 1800 | I56: 0.15 | J56: 1530 | K56: 124.36 | L56: Net Banking | M56: Online
A57: ORD-0056 | B57: 45897 | C57: CUST-0033 | D57: North | E57: Accessories | F57: USB Hub | G57: 1 | H57: 900 | I57: 0.15 | J57: 765 | K57: 37.65 | L57: Net Banking | M57: Online
A58: ORD-0057 | B58: 45683 | C58: CUST-0067 | D58: West | E58: Office Supplies | F58: Notebook | G58: 4 | H58: 120 | I58: 0.1 | J58: 432 | K58: 42.77 | L58: Net Banking | M58: Retail Store
A59: ORD-0058 | B59: 45873 | C59: CUST-0065 | D59: North | E59: Accessories | F59: USB Hub | G59: 6 | H59: 900 | I59: 0.2 | J59: 4320 | K59: 129.6 | L59: Debit Card | M59: Online
A60: ORD-0059 | B60: 45990 | C60: CUST-0018 | D60: North | E60: Electronics | F60: Monitor | G60: 2 | H60: 14500 | I60: 0 | J60: 29000 | K60: 5203 | L60: Credit Card | M60: Online
A61: ORD-0060 | B61: 45900 | C61: CUST-0030 | D61: South | E61: Accessories | F61: Webcam | G61: 3 | H61: 2200 | I61: 0.05 | J61: 6270 | K61: 999.71 | L61: UPI | M61: Online
A62: ORD-0061 | B62: 45817 | C62: CUST-0028 | D62: North | E62: Office Supplies | F62: Stapler | G62: 4 | H62: 220 | I62: 0.05 | J62: 836 | K62: 62.42 | L62: Credit Card | M62: Online
A63: ORD-0062 | B63: 46014 | C63: CUST-0078 | D63: North | E63: Electronics | F63: Keyboard | G63: 5 | H63: 1800 | I63: 0.15 | J63: 7650 | K63: 1020.08 | L63: UPI | M63: Retail Store
A64: ORD-0063 | B64: 45664 | C64: CUST-0108 | D64: West | E64: Electronics | F64: Headphones | G64: 3 | H64: 2500 | I64: 0.15 | J64: 6375 | K64: 896.77 | L64: Net Banking | M64: Online
A65: ORD-0064 | B65: 45925 | C65: CUST-0070 | D65: West | E65: Accessories | F65: Laptop Bag | G65: 6 | H65: 1800 | I65: 0.2 | J65: 8640 | K65: 457.43 | L65: Credit Card | M65: Online
... A189: ORD-0188 | B189: 45843 | C189: CUST-0074 | D189: North | E189: Accessories | F189: Laptop Bag | G189: 5 | H189: 1800 | I189: 0.1 | J189: 8100 | K189: 1434.1 | L189: Cash | M189: Online
A190: ORD-0189 | B190: 45723 | D190: West | E190: Office Supplies | F190: Printer Ink | G190: 5 | H190: 1600 | I190: 0.1 | J190: 7200 | K190: 1193.72 | L190: Credit Card | M190: Retail Store
...

Sheet Project_Guide
A1: PROJECT 1 — RETAIL SALES PERFORMANCE ANALYSIS
A3: Project Goal | B3: Analyze retail sales data in Excel to identify sales trends, product/category performance, regional performance, and profitability.
A4: Primary Tool | B4: Microsoft Excel
A5: Skills Practiced | B5: Data cleaning, formulas, sorting/filtering, PivotTables, KPI calculation, charts, business insights
A7: Business Questions | D7: Recommended Workflow
A8: 1. What are total sales and total profit? | D8: 1. Inspect the raw data
A9: 2. What is the monthly sales trend? | D9: 2. Identify and fix data-quality issues
A10: 3. Which product categories generate the most sales and profit? | D10: 3. Create calculated columns where needed
A11: 4. Which region contributes the most sales? | D11: 4. Build PivotTables
A12: 5. Which products have the highest sales? | D12: 5. Create charts
A13: 6. What is the average order value? | D13: 6. Build a one-page dashboard
A14: 7. How do discounts relate to profitability? | D14: 7. Write 4–6 business insights
A15: 8. Which sales channel performs better: Online or Retail Store?
A17: Important: Do the cleaning yourself. Do not jump directly to the dashboard. The goal is to demonstrate the complete analyst workflow.
A19: PROJECT SUMMARY
A20: Retail Sales Performance Analysis is an Excel-based data analytics project designed to inspect, clean, analyze, and visualize retail transaction data for 2025. The project uses Excel Tables, formulas, PivotTables, charts, KPIs, and a dashboard to evaluate sales, profitability, order volume, regional performance, category performance, sales channels, and discount-related profitability patterns.
A24: TOOLS USED
A25: Microsoft Excel — Data Cleaning, Formulas, PivotTables, Charts, Dashboard
A27: KEY ANALYTICAL AREAS
A28: Sales Performance | Profitability | Regional Analysis | Category Analysis | Product Analysis | Monthly Trends | Sales Channels | Discount Analysis
